SampleTradeData.csv
MICROSOFT SELL 27 1,APPLE BID 5 20 OFFER 5 25,TESLA BID 3 120 OFFER 7 150,SAMSUNG BID 10 140 BID 7 150 OFFER 14 180,MICROSOFT BID 25 3 OFFER 25 6,META BID 21 65 OFFER 35 85,NVIDIA BID 50 80 OFFER 100 90,GOOGLE BID 200 13 OFFER 100 19,REDCHIP BID 55 25 OFFER 80 30,META BUY 50 100,PHIZER SELL 100 67,APPLE BUY 5 30,REDCHIP SELL 5 30,SAMSUNG BUY 2 200,TESLA BUY 2 150,GOOGLE SELL 50 11,NVIDIA BUY 200 100,PHIZER BID 1000 77 OFFER 500 88
